Workbook

Sheet TSS-bestaande site Report
A1: 1 a. Site informatie algemeen
A3: Sitenummer | F3: Naam RPE | H3: Rijk, Henk
A4: Adres | F4: Datum TSS
A5: Postcode | F5: X- (uit ARM) | H5: 110089
A6: Plaats | F6: Y-( uit ARM ) | H6: 401475
A7: EMF status | C7: Site_EMF_Approved
A8: Parent-Child config | C8: Nee | F8: Child sitenummer
A10: Scope | C10: Scope- Antenne-BB/RAN Controller | E10: 105MHz 4x4 + 3.5GHz - Commscope 2.8m + AIR32xx - 6651/6655
C11: Tekening | E11: =IFERROR(VLOOKUP(E10,values!$AW:$AX,2,0),"") -> 36.1b
C12: =IF(COUNTIF($E$10,"*1.6m*"),VLOOKUP($E$11,values!$AX:$AY,2,0),"")
A14: 1 b. Aanwezig op de TSS:
A15: Naam: | E15: Functie: | H15: Bedrijf:
A16: Dormans, Dennis | E16: =IFERROR(VLOOKUP($A16,values!$BB:$BC,2,0),"") -> Verwerver | H16: =IFERROR(VLOOKUP($A16,values!$BB:$BD,3,0),"") -> Ericsson
E17: =IFERROR(VLOOKUP($A17,values!$BB:$BC,2,0),"") | H17: =IFERROR(VLOOKUP($A17,values!$BB:$BD,3,0),"")
E18: =IFERROR(VLOOKUP($A18,values!$BB:$BC,2,0),"") | H18: =IFERROR(VLOOKUP($A18,values!$BB:$BD,3,0),"")
J19: ASP
J20: LL
A22: 2 a. Huidige configuratie
A23: (In te vullen door de radioplanner)
B24: Systeem | C24: Frequentie | D24: Kast type | E24: DU type | F24: Type Radio sector 1 | G24: Type Radio sector 2 | H24: Type Radio sector 3 | I24: Tx unit
A25: Laagband | B25: LTE | C25: 700 | I25: Router 6671
B26: LTE | C26: 800 | D26: 6102V2 | E26: DUS41 | F26: RUS01 | G26: RUS01 | H26: RUS01
B27: GSM | C27: 900 | D27: 6102V2 | E27: DUG20 | F27: RUS02 | G27: RUS02 | H27: RUS02
A28: Middenband | B28: LTE | C28: 1400
A29: Hoogband | B29: LTE | C29: 1800 | D29: 6102V2 | E29: DUS41 | F29: RUS01 | G29: RUS01 | H29: RUS01
B30: LTE | C30: 2100
B31: LTE | C31: 2600
B32: 5G | C32: 3500 | E32: X
B34: Systeem | C34: Frequentie | D34: Combiner / Triplexer | E34: Splitter | F34: TMA | G34: RIU | H34: Batterijen
A35: Laagband | B35: 5G | C35: 700 | H35: Lead batterijen | J35: X
A36: Laagband | B36: LTE | C36: 800 | H36: Li-Ion batterijen | J36: X
B37: GSM | C37: 900 | H37: Batterijen in een kast die blijft staan. | J37: Geen actie.
A38: Middenband | B38: LTE | C38: 1400 | H38: LEAD batterijen in kast die weg moet. | J38: Kast incl. batterijen afvoeren.
A39: Hoogband | B39: LTE | C39: 1800 | F39: TMA | H39: Li-Ion batterijen in een kast die weg moet. | J39: Informeer Battery project team. Zij halen de 6613 weg voor herinzet.
B40: LTE | C40: 2100
B41: LTE | C41: 2600
B42: 5G | C42: 3500
A44: Antenne - Sector | B44: Antenne typenummer | D44: Azimuth | E44: ABH | F44: Antenne - Sector | G44: Antenne typenummer | I44: Azimuth | J44: ABH
A45: A1 - S1 | B45: Commscope RRZZV4-65D-R8NV1 (2.8) | D45: 60 | E45: 15.7 | F45: A2 - S1
A46: A1 - S2 | B46: Commscope RRZZV4-65D-R8NV1 (2.8) | D46: 180 | E46: 15.7 | F46: A2 - S2
...

Sheet TSS-nieuwbouw site Report
A1: 1 a. Site informatie algemeen
A3: Sitenummer | F3: Naam RPE | H3: Rayen Faeber
A4: Adres | F4: Datum TSS
A5: Postcode | F5: X- (uit ARM)
A6: Plaats | F6: Y-( uit ARM )
A7: Parent-Child config | C7: Ja | F7: Child sitenummer | H7: S17123
C9: Scope- Antenne-BB/RAN Controller | E9: 105MHZ 4x4 + 3.5GHz - Commscope 2.1 m Mosaic +AIR 32xx
C10: Tekening | E10: =IFERROR(VLOOKUP(E9,values!$AW:$AX,2,0),"") -> 37.1b
A12: 4.15 | B12: BB6651
A13: Naam: | E13: Functie: | H13: Bedrijf:
A14: Bronmans, Fred | E14: =IFERROR(VLOOKUP($A14,values!$BB:$BC,2,0),"") -> Site Engineer | H14: =IFERROR(VLOOKUP($A14,values!$BB:$BD,3,0),"") -> Ericsson
E15: =IFERROR(VLOOKUP($A15,values!$BB:$BC,2,0),"") | H15: =IFERROR(VLOOKUP($A15,values!$BB:$BD,3,0),"")
E16: =IFERROR(VLOOKUP($A16,values!$BB:$BC,2,0),"") | H16: =IFERROR(VLOOKUP($A16,values!$BB:$BD,3,0),"")
J18: ASP
J19: LL
A21: Constructie-/ mastberekeningen
A22: Constructieberekeningen
A23: Tekenpakket beschikbaar
A24: Dakplattegrond bestaande situatie
A25: Schoongrondverklaring/ onderzoek
A26: Funderingsadvies
A27: Vergunning/ gedoogbeschikking
A28: Aarding bliksem bestaande situatie
A29: kabelberekeningen elektra
A31: Opmerkingen:
A37: 3. Gebouw / Terrein
A38: Gebouwen algemeen (objecten)
A39: (aanvinken om wat het gaat )
A41: Monument | E41: Fabriek, silo | I41: Mast OLO
A42: Kerk | E42: Woongebouw | I42: Mast derden | J42: Y
A43: Kantoorgebouw | E43: Nieuwe mast
A45: Opmerkingen:
A51: 3a. Toegang
A53: Positie sleutelkluis bekend | F53: Aantal
A54: Aantal sleutels nodig, zo ja, hoeveel?
A56: Opmerkingen:
A60: 4. TYPE SITE
C62: Indoor | D62: Indien Special, wat voor object
C63: Outdoor
A65: Opmerkingen: (geef aan wat voor ruimte)
...

Sheet Checklist Fotodocumentatie
A3: 1. Overzicht van het gebouw (meerdere foto's)
A4: 2. Site overzicht van de apparatuur opstelling (meerdere foto's)
A5: 3. Overzicht van de binnenkant apparatuur (hardware)
A6: 4. Overzicht transmissie en de juiste lijnnummers
A8: 5. Overzicht RRU’s en werkplekken bij de RRU’s
A9: 6. Overzicht van de antennes
A10: 7. Duidelijk overzicht van de labels op de antennes
A11: 8. Overzicht van de jumpers / feeders
A12: 4.15
A13: 10. Overzicht van schotelopstelling
A15: 11. K1, K2 en/of Landlord verdeler (meerdere foto's)
A16: 12. Aarding (HAR / SAR / ringleiding)
... A34: Zorg dat alle foto's in een mapje staan. Maak een .zip file van het mapje en een ingevuld TSS document.

Sheet values
A1: Kast type | C1: DU type bestaande site | D1: DU type nieuwe site | F1: TX unit type bestaande site | G1: Router nieuwe site | I1: Radio type bestaande site | J1: Radio type nieuwe site | L1: Combiner/triplexer | N1: Splitter | O1: Type Diplexer | P1: Batterijen | R1: Rectifiers | T1: TMA/filter | V1: RIU | X1: 4x4 toepassen | Z1: PSU | AB1: Bliksembeveiliging | AD1: RPE naam | AF1: Aantal | AH1: Antenne typenummer bestaande site | AI1: Antenne typenummer nieuwe site | AK1: K1-Kast | AM1: Dakopbouw | AO1: Checklist grond | AQ1: Type Site | AS1: Dishes | AU1: Documentatie | AW1: Sunrise 3.1 scope | AX1: Aansluitschema | AY1: Opmerking standaard tek | BA1: Bedrijf | BB1: Naam ENN engineer | BC1: functie | BD1: Bedrijf | BH1: EMF
BH2: Site_EMF_Approved
AH3: 739650 | AW3: Scope - Antenne - BB | AX3: Tekening | AY3: Opm Tekening | BB3: Andringa, Jan | BC3: Site Engineer | BD3: Ericsson | BH3: Site_EMF_Rejected
A4: MMC | C4: DUG20 | D4: DUG20 | F4: SIU | G4: Router 6471 | I4: AIR11 | J4: AIR3278 | L4: 1x DI | N4: Y | O4: 78211471 | P4: Y | R4: 4 | T4: 1400 filter | V4: Y | X4: Y | Z4: Y | AB4: Y | AD4: Bollen, Arno | AF4: 0 | AH4: 3GPX0505F9 | AI4: Conform bestaand | AK4: Y | AM4: Goed | AO4: Y | AQ4: Rooftop | AS4: 300 | AU4: Ja | AW4: 105MHZ 4x4 + 3.5GHz - Commscope 2.8 m Mosaic +AIR 32xx | AX4: 37.1a | BA4: Circet Telecom | BB4: Bronmans, Fred | BC4: Site Engineer | BD4: Ericsson | BH4: Site_is_not_checked
A5: 6150 | C5: DUS31 | D5: BB6630 | F5: Router 6471 | G5: Router 6671 | I5: AIR21 | J5: AIR3258 | L5: 2x DI | N5: N | P5: N | R5: 5 | T5: TMA | V5: N | X5: N | Z5: N | AB5: N | AD5: Faeber, Rayen | AF5: 1 | AH5: 3LPX0505F9 | AI5: 3GPX0505F9 | AK5: N | AM5: Matig | AO5: N | AQ5: Groundsite | AS5: 600 | AU5: Nee | AW5: 105MHZ 4x4 + 3.5GHz - Commscope 2.1 m Mosaic +AIR 32xx | AX5: 37.1b | BA5: Dael Telecom | BB5: Coppers, Tom | BC5: Site Engineer | BD5: Ericsson | BH5: Check EMF on site
A6: 6201 | C6: DUS41 | D6: BB6631 | F6: Router 6671 | G6: Router 6672 | I6: AIR3258 | J6: AIR3258 achter Mosaic | L6: 3x DI | N6: X | P6: BBU 6613 | R6: 6 | T6: DTMA | V6: X | X6: X | AB6: NVT | AD6: Lazrag, Benaissa | AF6: 2 | AH6: A5NPX1006F | AI6: 3LPX0505F9 | AK6: Other | AM6: Slecht | AO6: Gemeente | AQ6: Greenfield | AU6: NVT | AW6: 105MHZ 4x4 + 3.5GHz - Commscope 1.6 m Mosaic +AIR 32xx | AX6: 37.1c | BA6: Dael Power | BB6: Derrez, Ischa | BC6: Site Engineer | BD6: Ericsson
A7: 6102V2 | C7: BB6630 | D7: RC6651 | F7: Router 6672 | I7: AIR3278 | J7: X | L7: 4x DI | P7: 3xBBU 6618 | T7: ASC | AB7: NTB | AD7: Mahaboeb, Ibrahim | AF7: 3 | AH7: AD7210_0 | AI7: A5NPX1006F | AM7: zie foto's | AQ7: HVP | AU7: Niet leverbaar | AW7: 105MHz 4x4 + 3.5GHz - Commscope 2.8m + AIR32xx - 6651/6655 | AX7: 36.1b | BA7: Dynamica | BB7: Heres, Maarten | BC7: Site Engineer | BD7: Ericsson
A8: Power 6210 | C8: BB6631 | D8: RC6655 | I8: 2012 | J8: 2012 | L8: 1x TRI | T8: X | AD8: Rijk, Henk | AF8: 4 | AH8: AD7210_6 | AI8: AIR3258 | AQ8: Church | AU8: Wordt opgevraagd | AW8: 105MHz 4x4 + 3.5GHz - Commscope 1.6m + AIR32xx - 6651/6655 | AX8: Excel 36.31b | AY8: tek van 36.11b gebruiken (koptekst en antenne type aanpassen) | BA8: Ericsson | BB8: Huizinga, Ronald | BC8: Site Engineer | BD8: Ericsson
A9: Indoor | C9: BB6648 | D9: X | I9: 2212 | J9: 2242 | L9: 2x TRI | P9: X | AD9: Spaan, Erik | AF9: 5 | AH9: AD7210_6_6DB | AI9: AIR3258 achter Mosaic | AQ9: Special, vermelden wat | AW9: 105MHZ 4x4 - Commscope 2.8 m Mosaic ( zonder 5G3500), BB6631 | AX9: 37.1a aanpassen | BA9: Bouwbedrijf Hendriks | BB9: Klompmakers, John | BC9: Site Engineer | BD9: Ericsson
A10: ITC | C10: RC6651 | I10: 2217 | J10: 2260 | L10: 3x TRI | AH10: ADU4518R7v06 | AI10: AOC4518R21v06 | AQ10: Y | AW10: 105MHZ 4x4 - Commscope 2.1 m Mosaic ( zonder 5G3500),BB6631 | AX10: 37.1b aanpassen | BA10: MD7 | BB10: Malone, Floyd | BC10: Site Engineer | BD10: Ericsson
A11: other | C11: RC6655 | I11: 2219 | J11: 2460 | L11: 4x TRI | AH11: AIR11 | AI11: AOC4518R6v06 | AQ11: N | AW11: 105MHZ 4x4 - Commscope 1.6 m Mosaic ( zonder 5G3500),BB6631 | AX11: 37.1c aanpassen | BA11: Octalon | BB11: Maly, Martin | BC11: Site Engineer | BD11: Ericsson
A12: X | C12: DUW30 | I12: 2242 | J12: 4020 | L12: N | AH12: AIR21 | AI12: AOC4518R7v06 | AW12: 105MHz 4x4 + 3.5GHz - Commscope 2.1m + AIR32xx - 6651/6655 | AX12: 36.11b | BA12: Turris - NMS | BB12: Ommeren van, Jimmy | BC12: Site Engineer | BD12: Ericsson
C13: DUW41 | I13: 2260 | J13: 4415 | L13: X | AH13: AIR3258 | AI13: AQU4518R60v06 | AQ13: Anders | AW13: 105MHz 4x4 - Commscope 1.6m - 6651/6655 | AX13: Excel 36.31f | AY13: tek van 36.11f gebruiken (koptekst en antenne type aanpassen) | BA13: Spie | BB13: Sewradj, Vijayanand | BC13: Site Engineer | BD13: Ericsson
C14: X | I14: 2460 | J14: 4471 | AH14: AIR3278 | AI14: ASI4518R36v06 | AQ14: Cellnex | AW14: 105MHz 4x4 - Commscope 2.8m - 6651/6655 | AX14: 36.1f | BA14: Vodafone | BB14: Verhoeff, Patrick | BC14: Site Engineer | BD14: Ericsson
I15: 4020 | J15: 4480 | AH15: AL4158.11.33_6 | AI15: ASI4518R37v06 | AQ15: KPN | AW15: 105MHz 4x4 - Commscope 2.1m - 6651/6655 | AX15: 36.11f | BA15: WL Winet | BB15: Wezel, Henk Van | BC15: Site Engineer | BD15: Ericsson
I16: 4415 | J16: 4490 | AH16: AL7125.19 | AI16: ASI4518R39v06 | AQ16: Althio | AW16: 105MHz 4x4 - Commscope 2.8m - 2 x 6630 | AX16: 36.1d | BB16: Woerlee, Rene | BC16: Site Engineer | BD16: Ericsson
A17: MMC | I17: 4471 | J17: X | AH17: AL7191.01 | AI17: HAOC4518R6v06 | AQ17: Odido | AW17: 105MHz 4x4 - Commscope 2.1m - 2 x 6630 | AX17: 36.11d | BA17: X | BB17: Wolthuis, Wouter | BC17: Site Engineer | BD17: Ericsson
A18: 6150 | I18: 4480 | AH18: AOC4518R21v06 | AI18: Commscope Mosaic (2,8m) RRYYV4-65D-R6-U | AW18: 105MHz 4x4 - Commscope 1.6m - 2 x 6630 | AX18: Excel 36.31d | AY18: tek van 36.11d gebruiken (koptekst en antenne type aanpassen) | BB18: Olejnik, Tobias | BC18: Site Engineer | BD18: Ericsson
A19: 6201 | C19: DUG20 | I19: 4490 | AH19: AOC4518R6v06 | AI19: Commscope Mosaic (2,1m) RRZZHHTT-65B-R6-U | AW19: 75MHz 4x4 + 3.5GHz - Commscope 2.8 m Mosaic +AIR 32xx | AX19: 36.3h | BB19: Bollen, Arno | BC19: Radio Engineer | BD19: Ericsson
A20: Power 6210 | C20: DUS31 | I20: RRUS01 | AH20: AOC4518R7v06 | AI20: Commscope RRZZ-33D-R4 | AW20: 75MHZ 4x4 - Commscope 2.8 m Mosaic (zonder 5G3500), BB6631 | AX20: 37.1a aanpassen | BB20: Faeber, Rayen | BC20: Radio Engineer | BD20: Ericsson
A21: 6102V2 | C21: DUS41 | I21: RRUS11 | AH21: AQU4518R60v06 | AI21: Commscope RRZZHHTT-65A-R7N43F (1.6) | AW21: 75MHZ 4x4 - Commscope 2.1 m Mosaic (met/zonder 5G3500), BB6631 | AX21: 37.1b aanpassen | BB21: Lazrag, Benaissa | BC21: Radio Engineer | BD21: Ericsson
A22: 3101 | C22: DUL20 | I22: RRUS12 | AH22: ASI4518R36v06 | AI22: Commscope RRZZHHTT-65B-R7N43 (2.1) | AW22: 75MHZ 4x4 - Commscope 1.6 m Mosaic (met/zonder 5G3500), BB6631 | AX22: 37.1c aanpassen | BB22: Mahaboeb, Ibrahim | BC22: Radio Engineer | BD22: Ericsson
A23: 3106 | C23: BB6630 | I23: RRUW01 | AH23: ASI4518R37v06 | AI23: Commscope RRZZV4-65D-R8NV1 (2.8) | AW23: 75MHz 4x4 + 3.5GHz - Commscope 2.8m + AIR32xx - 6651/6655 | AX23: 36.3b | BB23: Rijk, Henk | BC23: Radio Engineer | BD23: Ericsson
A24: 2102 | C24: BB6631 | I24: RUS01 | AH24: ASI4518R39v06 | AI24: Commscope buis GGGO310R3 | AW24: 75MHz 4x4 + 3.5GHz - Commscope 2.1m + AIR32xx - 6651/6655 | AX24: 36.13b | BB24: Spaan, Erik | BC24: Radio Engineer | BD24: Ericsson
A25: 2106 | C25: BB6648 | I25: RUS02 | AH25: BSA_W65 | AI25: K800372965 | AW25: 75MHz 4x4 + 3.5GHz - Commscope 1.6m + AIR32xx - 6651/6655 | AX25: Excel 36.33b | AY25: tek van 36.13b gebruiken (koptekst en antenne type aanpassen) | BB25: Dormans, Dennis | BC25: Verwerver | BD25: Ericsson
A26: 3303 | C26: RC6651 | I26: RUW01 | AH26: Commscope RRZZV4-65D-R8NV1 (2.8) | AI26: K800372966 | AW26: 75MHz 4x4 - Commscope 2.8m - 6631 | AX26: 36.3d | BB26: Homringhausen, Tanja | BC26: Verwerver | BD26: Ericsson-Duvekot
A27: 3418 | C27: DUW10 | I27: X | AH27: Commscope RRZZHHTT-65B-R7N43 (2.1) | AI27: Other, zie comments | AW27: 75MHz 4x4 - Commscope 2.1m - 6631 | AX27: 36.13d | BB27: Hosny, Karim | BC27: Verwerver | BD27: Ericsson
A28: 3206 | C28: DUW20 | AH28: Commscope RRZZHHTT-65A-R7N43F (1.6) | AW28: 75MHz 4x4 - Commscope 1.6m - 6631 | AX28: Excel 36.33d | AY28: tek van 36.13d gebruiken (koptekst en antenne type aanpassen) | BB28: Kos, Lennaert | BC28: Verwerver | BD28: Ericsson-INSSO
A29: 3202 | C29: DUW30 | AH29: Commscope Mosaic (2,8m) RRYYV4-65D-R6-U | AW29: 75MHz 4x4 - Commscope 2.8m - 2 x 6630 | AX29: 36.3f | BB29: Kuil, van der , Bart | BC29: Verwerver | BD29: Ericsson-INSSO
A30: 3201 | C30: DUW41 | AH30: Commscope Mosaic (2,1m) RRZZHHTT-65B-R6-U | AW30: 75MHz 4x4 - Commscope 2.1m - 2 x 6630 | AX30: 36.13f | BB30: Moeliker, Joep | BC30: Verwerver | BD30: Ericsson-Vamea
A31: 2308 | C31: MCPA | AH31: DB992HG28N-B | AW31: 75MHz 4x4 - Commscope 1.6m - 2 x 6630 | AX31: Excel 36.33f | AY31: tek van 36.13f gebruiken (koptekst en antenne type aanpassen) | BB31: Nicolai, Norbert | BC31: Verwerver | BD31: Ericsson-INSSO
A32: ITC | C32: CDU | AH32: DOT1800 | AW32: 75MHz 2x2 - Commscope 2.8m - 2 x 6630 | AX32: 36.4b | BB32: Spanjers, Axel | BC32: Verwerver | BD32: Ericsson-Vamea
A33: X | C33: X | AH33: DOT2100 | AW33: 75MHz 2x2 - Commscope 2.1m - 2 x 6630 | AX33: 36.14b | BB33: Voorpostel, Bastiaan | BC33: Verwerver | BD33: Ericsson-Duvekot
A34: Indoor | AH34: DOT2600 | AW34: 75MHz 2x2 - Commscope 1.6m - 2 x 6630 | AX34: Excel 36.34b | AY34: tek van 36.14b gebruiken (koptekst en antenne type aanpassen) | BB34: Michelon, David | BC34: Verwerver | BD34: MD7
A35: other | AH35: GGGO310R3 | AW35: 75MHz 2x2 - Commscope 2.8m - 6631 | AX35: 36.4d | BB35: Kuipers, Marc | BC35: Verwerver | BD35: MD7
AH36: HA264518R0 | AW36: 75 MHz 2x2 - Commscope 1.6m - 6631 | AX36: 36.34d | AY36: tek van 36.14d gebruiken (koptekst en antennetype aanpassen) | BB36: Kerkhoff, Mark | BC36: Verwerver | BD36: MD7
AH37: HA264518R0v01 | AW37: 75MHz 2x2 - Commscope 2.1m - 6631 | AX37: 36.14d | BB37: Noordam, Rutger | BC37: Verwerver | BD37: MD7
AH38: HA264518R0v06 | AW38: 60MHz 4x4 + 3.5GHz - Commscope 2.8m + AIR 32xx - 6651/6655 | AX38: 36.4f | BB38: Habets, Michael | BC38: Acc. manager | BD38: MD7
AH39: HA704515R0 | AW39: 60MHz 4x4 + 3.5GHz - Commscope 2.1m + AIR 32xx - 6651/6655 | AX39: 36.14f | BB39: Lugtigheid, Dennis | BC39: Acc. manager | BD39: Ericsson
AH40: HA704515R0v06 | AW40: 60MHz 4x4 + 3.5GHz - Commscope 1.6m + AIR32xx - 6651/6655 | AX40: Excel 36.34f | AY40: tek van 36.14f gebruiken (koptekst en antennetype aanpassen) | BB40: Opdorp van, JP | BC40: Acc. manager | BD40: Ericsson
...

Sheet Revisies
A1: Revisienr | B1: Wijziging | C1: Door | D1: Datum
A2: 4.5 | B2: Upgrade ivm VFZ guidelines 2.59 Scope-Tekening verwijzing, Air 3278 antenne, mast OLO-VF-derden. | C2: WW & EvdM | D2: 44847
A3: 4.6 | B3: Extra rectifiers 6150 gebaseerd op scope, Upgrade verwijzing tekeningen met Huawei antennes gebaseerd op VFZ guideline 2.6. De licht roze cellen bevatten formules. | C3: EvdM | D3: 44860
A4: 4.7 | B4: Toevoeging tek nrs Commscope 1,6m antennes, tekst 4.b, EMF informatie en inventarisatie batterijen (regel 32-36). | C4: EvdM | D4: 44910
A5: 4.8 | B5: Toegevoegd Fred Bronmans en Genno Woerlee. | C5: EvdM | D5: 44943
A6: 4.9 | B6: L0700 aangepast naar 5G0700, toegevoegd 3 verwervers. | C6: EvdM | D6: 45299
A7: 4.10 | B7: Toegevoegd Radio 4490, verwijderd Radio 4480, BB6630 verwijderd, BB6631 toegevoegd. Toegevoegd: Transmissie vraag om MPO connector te verplaatsen. | C7: EvdM | D7: 45320
A8: 4.11 | B8: Nieuwe SEN's RPE's | C8: EvdM | D8: 45366
A9: 4.12 | B9: Nieuwe Commscope antennes (Mosaic en 33 graden), AIR 3278, Power 6210, aanpassing namen SEN en verwervers | C9: EvdM | D9: 45492
A10: 4.13 | B10: Tek verwijzing Commscope Mosaic, bestaande configs uitgebreid met 4020 en 4490. TX unit. Parent-Child. Enkele formules. | C10: EvdM | D10: 45538
A11: 4.14 | B11: AIR 3278 vervallen, AIR 3258 als enkele selecteerbare antenne toegevoegd. | C11: EvdM | D11: 45575
A12: 4.15 | B12: RP6655, Mosaic antenne 2,10m, Prep 2600 vervallen, niet te gebruiken antennes en configuraties opgeschoond. | C12: EvdM | D12: 45796
A13: 4.16 | B13: Tekening Commscope Mosaic 2.10 en 1.6m, ASP, Batterijen 6618 bij nieuwe Enclosures. | C13: EvdM | D13: 45905
... A17: 4.20 | B17: Toegevoegd Radio 4471, vervangt Radio 4415 op B7 2600 | C17: EvdM | D17: 46199
